Workbook

Sheet Weather_Data
A1: Location | B1: Latitude | C1: Longitude | D1: Elevation_m | E1: Region_Climate_Type | F1: Month | G1: Month_Number | H1: Season | I1: Date_Representative | J1: Location_Month_Key | K1: Outdoor_Temperature_C | L1: Relative_Humidity_pct | M1: Wind_Speed_ms | N1: Wind_Direction | O1: Solar_kWh_m2_day | P1: Solar_Radiation_Wm2 | Q1: Rainfall_mm | R1: Seasonal_Pressure_Adjustment_hPa | S1: Atmospheric_Pressure_hPa | T1: Data_Source_Label
A2: Leh | B2: 34.15 | C2: 77.58 | D2: 3500 | E2: Cold high-altitude desert | F2: January | G2: 1 | H2: Winter | I2: 2024-01-15 | J2: =A2&"-"&F2 -> Leh-January | K2: -8 | L2: 25 | M2: 2 | N2: NW | O2: 4 | P2: =O2*1000/24 -> 166.66667 | Q2: 5 | R2: 2 | S2: =1013.25*(1-0.0000225577*D2)^5.25588+R2 -> 659.64058 | T2: SYNTHETIC/REPRESENTATIVE - illustrative monthly climatology pattern based on general published climate characteristics of each location; NOT actual IMD historical observations. Validate against IMD 1991-2020 normals or NASA POWER before final use.
A3: Leh | B3: 34.15 | C3: 77.58 | D3: 3500 | E3: Cold high-altitude desert | F3: February | G3: 2 | H3: Winter | I3: 2024-02-15 | J3: =A3&"-"&F3 -> Leh-February | K3: -5 | L3: 25 | M3: 2.5 | N3: NW | O3: 4.5 | P3: =O3*1000/24 -> 187.5 | Q3: 5 | R3: 1.5 | S3: =1013.25*(1-0.0000225577*D3)^5.25588+R3 -> 659.14058 | T3: SYNTHETIC/REPRESENTATIVE - illustrative monthly climatology pattern based on general published climate characteristics of each location; NOT actual IMD historical observations. Validate against IMD 1991-2020 normals or NASA POWER before final use.
A4: Leh | B4: 34.15 | C4: 77.58 | D4: 3500 | E4: Cold high-altitude desert | F4: March | G4: 3 | H4: Spring/Pre-monsoon | I4: 2024-03-15 | J4: =A4&"-"&F4 -> Leh-March | K4: 1 | L4: 28 | M4: 3.5 | N4: W | O4: 5.5 | P4: =O4*1000/24 -> 229.16667 | Q4: 8 | R4: 1 | S4: =1013.25*(1-0.0000225577*D4)^5.25588+R4 -> 658.64058 | T4: SYNTHETIC/REPRESENTATIVE - illustrative monthly climatology pattern based on general published climate characteristics of each location; NOT actual IMD historical observations. Validate against IMD 1991-2020 normals or NASA POWER before final use.
A5: Leh | B5: 34.15 | C5: 77.58 | D5: 3500 | E5: Cold high-altitude desert | F5: April | G5: 4 | H5: Spring/Pre-monsoon | I5: 2024-04-15 | J5: =A5&"-"&F5 -> Leh-April | K5: 7 | L5: 30 | M5: 4 | N5: W | O5: 6.5 | P5: =O5*1000/24 -> 270.83333 | Q5: 10 | R5: 0 | S5: =1013.25*(1-0.0000225577*D5)^5.25588+R5 -> 657.64058 | T5: SYNTHETIC/REPRESENTATIVE - illustrative monthly climatology pattern based on general published climate characteristics of each location; NOT actual IMD historical observations. Validate against IMD 1991-2020 normals or NASA POWER before final use.
A6: Leh | B6: 34.15 | C6: 77.58 | D6: 3500 | E6: Cold high-altitude desert | F6: May | G6: 5 | H6: Summer/Pre-monsoon | I6: 2024-05-15 | J6: =A6&"-"&F6 -> Leh-May | K6: 12 | L6: 32 | M6: 4 | N6: SW | O6: 7 | P6: =O6*1000/24 -> 291.66667 | Q6: 10 | R6: -1 | S6: =1013.25*(1-0.0000225577*D6)^5.25588+R6 -> 656.64058 | T6: SYNTHETIC/REPRESENTATIVE - illustrative monthly climatology pattern based on general published climate characteristics of each location; NOT actual IMD historical observations. Validate against IMD 1991-2020 normals or NASA POWER before final use.
A7: Leh | B7: 34.15 | C7: 77.58 | D7: 3500 | E7: Cold high-altitude desert | F7: June | G7: 6 | H7: Monsoon | I7: 2024-06-15 | J7: =A7&"-"&F7 -> Leh-June | K7: 16 | L7: 35 | M7: 3.5 | N7: SW | O7: 7.2 | P7: =O7*1000/24 -> 300 | Q7: 8 | R7: -2 | S7: =1013.25*(1-0.0000225577*D7)^5.25588+R7 -> 655.64058 | T7: SYNTHETIC/REPRESENTATIVE - illustrative monthly climatology pattern based on general published climate characteristics of each location; NOT actual IMD historical observations. Validate against IMD 1991-2020 normals or NASA POWER before final use.
A8: Leh | B8: 34.15 | C8: 77.58 | D8: 3500 | E8: Cold high-altitude desert | F8: July | G8: 7 | H8: Monsoon | I8: 2024-07-15 | J8: =A8&"-"&F8 -> Leh-July | K8: 19 | L8: 38 | M8: 3 | N8: SW | O8: 6.8 | P8: =O8*1000/24 -> 283.33333 | Q8: 15 | R8: -2 | S8: =1013.25*(1-0.0000225577*D8)^5.25588+R8 -> 655.64058 | T8: SYNTHETIC/REPRESENTATIVE - illustrative monthly climatology pattern based on general published climate characteristics of each location; NOT actual IMD historical observations. Validate against IMD 1991-2020 normals or NASA POWER before final use.
A9: Leh | B9: 34.15 | C9: 77.58 | D9: 3500 | E9: Cold high-altitude desert | F9: August | G9: 8 | H9: Monsoon | I9: 2024-08-15 | J9: =A9&"-"&F9 -> Leh-August | K9: 18 | L9: 38 | M9: 3 | N9: SW | O9: 6.5 | P9: =O9*1000/24 -> 270.83333 | Q9: 15 | R9: -2 | S9: =1013.25*(1-0.0000225577*D9)^5.25588+R9 -> 655.64058 | T9: SYNTHETIC/REPRESENTATIVE - illustrative monthly climatology pattern based on general published climate characteristics of each location; NOT actual IMD historical observations. Validate against IMD 1991-2020 normals or NASA POWER before final use.
A10: Leh | B10: 34.15 | C10: 77.58 | D10: 3500 | E10: Cold high-altitude desert | F10: September | G10: 9 | H10: Monsoon | I10: 2024-09-15 | J10: =A10&"-"&F10 -> Leh-September | K10: 14 | L10: 35 | M10: 3 | N10: W | O10: 6 | P10: =O10*1000/24 -> 250 | Q10: 8 | R10: -1 | S10: =1013.25*(1-0.0000225577*D10)^5.25588+R10 -> 656.64058 | T10: SYNTHETIC/REPRESENTATIVE - illustrative monthly climatology pattern based on general published climate characteristics of each location; NOT actual IMD historical observations. Validate against IMD 1991-2020 normals or NASA POWER before final use.
A11: Leh | B11: 34.15 | C11: 77.58 | D11: 3500 | E11: Cold high-altitude desert | F11: October | G11: 10 | H11: Post-monsoon/Autumn | I11: 2024-10-15 | J11: =A11&"-"&F11 -> Leh-October | K11: 7 | L11: 30 | M11: 2.5 | N11: W | O11: 5 | P11: =O11*1000/24 -> 208.33333 | Q11: 3 | R11: 0 | S11: =1013.25*(1-0.0000225577*D11)^5.25588+R11 -> 657.64058 | T11: SYNTHETIC/REPRESENTATIVE - illustrative monthly climatology pattern based on general published climate characteristics of each location; NOT actual IMD historical observations. Validate against IMD 1991-2020 normals or NASA POWER before final use.
A12: Leh | B12: 34.15 | C12: 77.58 | D12: 3500 | E12: Cold high-altitude desert | F12: November | G12: 11 | H12: Post-monsoon/Autumn | I12: 2024-11-15 | J12: =A12&"-"&F12 -> Leh-November | K12: -1 | L12: 27 | M12: 2 | N12: NW | O12: 4.2 | P12: =O12*1000/24 -> 175 | Q12: 2 | R12: 1 | S12: =1013.25*(1-0.0000225577*D12)^5.25588+R12 -> 658.64058 | T12: SYNTHETIC/REPRESENTATIVE - illustrative monthly climatology pattern based on general published climate characteristics of each location; NOT actual IMD historical observations. Validate against IMD 1991-2020 normals or NASA POWER before final use.
A13: Leh | B13: 34.15 | C13: 77.58 | D13: 3500 | E13: Cold high-altitude desert | F13: December | G13: 12 | H13: Winter | I13: 2024-12-15 | J13: =A13&"-"&F13 -> Leh-December | K13: -6 | L13: 25 | M13: 2 | N13: NW | O13: 3.8 | P13: =O13*1000/24 -> 158.33333 | Q13: 3 | R13: 2 | S13: =1013.25*(1-0.0000225577*D13)^5.25588+R13 -> 659.64058 | T13: SYNTHETIC/REPRESENTATIVE - illustrative monthly climatology pattern based on general published climate characteristics of each location; NOT actual IMD historical observations. Validate against IMD 1991-2020 normals or NASA POWER before final use.
... A73: Chennai | B73: 13.08 | C73: 80.27 | D73: 6 | E73: Hot-humid coastal (tropical) | F73: December | G73: 12 | H73: Winter | I73: 2024-12-15 | J73: =A73&"-"&F73 -> Chennai-December | K73: 25 | L73: 78 | M73: 4 | N73: NE | O73: 4 | P73: =O73*1000/24 -> 166.66667 | Q73: 180 | R73: 2 | S73: =1013.25*(1-0.0000225577*D73)^5.25588+R73 -> 1014.5294 | T73: SYNTHETIC/REPRESENTATIVE - illustrative monthly climatology pattern based on general published climate characteristics of each location; NOT actual IMD historical observations. Validate against IMD 1991-2020 normals or NASA POWER before final use.

Sheet Material_Properties
A1: Material_ID | B1: Material_Name | C1: Material_Category | D1: Thermal_Conductivity_k_WmK | E1: Density_kgm3 | F1: Specific_Heat_JkgK | G1: Emissivity | H1: Thickness_Min_mm | I1: Thickness_Max_mm | J1: Thickness_Mid_mm | K1: Thermal_Resistance_R_m2KW | L1: Moisture_Resistance | M1: Durability | N1: Weight_Category | O1: Approximate_Relative_Cost | P1: Suitability_Cold_Climate | Q1: Suitability_Hot_Dry_Climate | R1: Suitability_Hot_Humid_Climate | S1: Suitability_Temporary_Shelter | T1: Advantages | U1: Limitations | V1: Data_Source_Label
A2: M01 | B2: Concrete | C2: Masonry | D2: 1.4 | E2: 2400 | F2: 880 | G2: 0.9 | H2: 100 | I2: 300 | J2: =AVERAGE(H2,I2) -> 200 | K2: =(J2/1000)/D2 -> 0.14285714 | L2: Medium-High | M2: High | N2: =IF(E2<200,"Light",IF(E2<1000,"Medium","Heavy")) -> Heavy | O2: Medium | P2: Partial | Q2: Yes | R2: Partial | S2: No | T2: High thermal mass, structurally robust | U2: Heavy, poor insulator alone, needs added insulation for cold climates | V2: SYNTHETIC/REFERENCE - typical values at the level of standard engineering literature (ASHRAE Fundamentals-type ranges); validate against manufacturer datasheets or measured lab data before final use.
A3: M02 | B3: Brick | C3: Masonry | D3: 0.7 | E3: 1750 | F3: 840 | G3: 0.93 | H3: 100 | I3: 230 | J3: =AVERAGE(H3,I3) -> 165 | K3: =(J3/1000)/D3 -> 0.23571429 | L3: Medium | M3: High | N3: =IF(E3<200,"Light",IF(E3<1000,"Medium","Heavy")) -> Heavy | O3: Low-Medium | P3: Partial | Q3: Yes | R3: Partial | S3: No | T3: Locally available, good thermal mass, fire-resistant | U3: Heavy, requires skilled labour, poor insulation alone | V3: SYNTHETIC/REFERENCE - typical values at the level of standard engineering literature (ASHRAE Fundamentals-type ranges); validate against manufacturer datasheets or measured lab data before final use.
A4: M03 | B4: Steel (structural sheet) | C4: Metal | D4: 47 | E4: 7850 | F4: 490 | G4: 0.2 | H4: 1 | I4: 5 | J4: =AVERAGE(H4,I4) -> 3 | K4: =(J4/1000)/D4 -> 6.3829787e-05 | L4: Medium (bare)/High (coated) | M4: High | N4: =IF(E4<200,"Light",IF(E4<1000,"Medium","Heavy")) -> Heavy | O4: Medium-High | P4: No | Q4: Partial | R4: Partial | S4: Yes | T4: Strong, fast assembly, good strength-to-weight | U4: Very poor insulator alone; overheats in direct sun without insulation | V4: SYNTHETIC/REFERENCE - typical values at the level of standard engineering literature (ASHRAE Fundamentals-type ranges); validate against manufacturer datasheets or measured lab data before final use.
A5: M04 | B5: Aluminium (sheet) | C5: Metal | D5: 205 | E5: 2700 | F5: 900 | G5: 0.2 | H5: 1 | I5: 5 | J5: =AVERAGE(H5,I5) -> 3 | K5: =(J5/1000)/D5 -> 1.4634146e-05 | L5: High | M5: Medium-High | N5: =IF(E5<200,"Light",IF(E5<1000,"Medium","Heavy")) -> Heavy | O5: High | P5: No | Q5: Partial | R5: Partial | S5: Yes | T5: Very lightweight, corrosion resistant, easy to transport to remote sites | U5: Extremely high conductivity - unusable as insulator without added layer | V5: SYNTHETIC/REFERENCE - typical values at the level of standard engineering literature (ASHRAE Fundamentals-type ranges); validate against manufacturer datasheets or measured lab data before final use.
A6: M05 | B6: Plywood | C6: Wood-based | D6: 0.13 | E6: 560 | F6: 1600 | G6: 0.9 | H6: 9 | I6: 25 | J6: =AVERAGE(H6,I6) -> 17 | K6: =(J6/1000)/D6 -> 0.13076923 | L6: Low-Medium | M6: Medium | N6: =IF(E6<200,"Light",IF(E6<1000,"Medium","Heavy")) -> Medium | O6: Medium | P6: Partial | Q6: Partial | R6: No | S6: Yes | T6: Easy to work with, moderate insulation, lightweight | U6: Vulnerable to moisture/humidity, moderate outdoor durability | V6: SYNTHETIC/REFERENCE - typical values at the level of standard engineering literature (ASHRAE Fundamentals-type ranges); validate against manufacturer datasheets or measured lab data before final use.
A7: M06 | B7: Timber (softwood) | C7: Wood | D7: 0.14 | E7: 550 | F7: 1700 | G7: 0.9 | H7: 20 | I7: 50 | J7: =AVERAGE(H7,I7) -> 35 | K7: =(J7/1000)/D7 -> 0.25 | L7: Low-Medium | M7: Medium | N7: =IF(E7<200,"Light",IF(E7<1000,"Medium","Heavy")) -> Medium | O7: Medium | P7: Yes | Q7: Partial | R7: No | S7: Yes | T7: Naturally insulating, renewable, workable by hand | U7: Combustible, moisture-sensitive, limited availability at high altitude | V7: SYNTHETIC/REFERENCE - typical values at the level of standard engineering literature (ASHRAE Fundamentals-type ranges); validate against manufacturer datasheets or measured lab data before final use.
A8: M07 | B8: EPS (Expanded Polystyrene) | C8: Insulation | D8: 0.036 | E8: 20 | F8: 1300 | G8: 0.6 | H8: 25 | I8: 150 | J8: =AVERAGE(H8,I8) -> 87.5 | K8: =(J8/1000)/D8 -> 2.4305556 | L8: Medium | M8: Medium | N8: =IF(E8<200,"Light",IF(E8<1000,"Medium","Heavy")) -> Light | O8: Low-Medium | P8: Yes | Q8: Yes | R8: Yes | S8: Yes | T8: Very light, good insulation, inexpensive | U8: UV-degradable if exposed, low structural strength, flammable untreated | V8: SYNTHETIC/REFERENCE - typical values at the level of standard engineering literature (ASHRAE Fundamentals-type ranges); validate against manufacturer datasheets or measured lab data before final use.
A9: M08 | B9: XPS (Extruded Polystyrene) | C9: Insulation | D9: 0.031 | E9: 35 | F9: 1450 | G9: 0.6 | H9: 25 | I9: 100 | J9: =AVERAGE(H9,I9) -> 62.5 | K9: =(J9/1000)/D9 -> 2.016129 | L9: High | M9: Medium-High | N9: =IF(E9<200,"Light",IF(E9<1000,"Medium","Heavy")) -> Light | O9: Medium | P9: Yes | Q9: Yes | R9: Yes | S9: Yes | T9: Closed-cell structure gives high moisture resistance and good insulation | U9: Higher cost than EPS, still needs UV protection | V9: SYNTHETIC/REFERENCE - typical values at the level of standard engineering literature (ASHRAE Fundamentals-type ranges); validate against manufacturer datasheets or measured lab data before final use.
A10: M09 | B10: Mineral wool | C10: Insulation | D10: 0.04 | E10: 60 | F10: 900 | G10: 0.9 | H10: 50 | I10: 200 | J10: =AVERAGE(H10,I10) -> 125 | K10: =(J10/1000)/D10 -> 3.125 | L10: Low | M10: Medium | N10: =IF(E10<200,"Light",IF(E10<1000,"Medium","Heavy")) -> Light | O10: Medium | P10: Yes | Q10: Partial | R10: No | S10: Partial | T10: Fire-resistant, good acoustic + thermal insulation | U10: Absorbs moisture and loses performance if wet, needs vapour barrier | V10: SYNTHETIC/REFERENCE - typical values at the level of standard engineering literature (ASHRAE Fundamentals-type ranges); validate against manufacturer datasheets or measured lab data before final use.
A11: M10 | B11: Fiberglass insulation | C11: Insulation | D11: 0.038 | E11: 24 | F11: 840 | G11: 0.9 | H11: 50 | I11: 200 | J11: =AVERAGE(H11,I11) -> 125 | K11: =(J11/1000)/D11 -> 3.2894737 | L11: Low-Medium | M11: Medium | N11: =IF(E11<200,"Light",IF(E11<1000,"Medium","Heavy")) -> Light | O11: Low-Medium | P11: Yes | Q11: Partial | R11: No | S11: Partial | T11: Widely available, inexpensive, good thermal performance | U11: Irritant during handling, performance drops if compressed/wet | V11: SYNTHETIC/REFERENCE - typical values at the level of standard engineering literature (ASHRAE Fundamentals-type ranges); validate against manufacturer datasheets or measured lab data before final use.
A12: M11 | B12: Polyurethane/PIR insulation | C12: Insulation | D12: 0.025 | E12: 35 | F12: 1450 | G12: 0.9 | H12: 25 | I12: 100 | J12: =AVERAGE(H12,I12) -> 62.5 | K12: =(J12/1000)/D12 -> 2.5 | L12: High | M12: High | N12: =IF(E12<200,"Light",IF(E12<1000,"Medium","Heavy")) -> Light | O12: High | P12: Yes | Q12: Yes | R12: Yes | S12: Partial | T12: Best-in-class insulation value (lowest k), thin profile for given R-value | U12: Highest cost among common insulators, needs fire-rated facing | V12: SYNTHETIC/REFERENCE - typical values at the level of standard engineering literature (ASHRAE Fundamentals-type ranges); validate against manufacturer datasheets or measured lab data before final use.
A13: M12 | B13: Canvas/fabric (tent material) | C13: Fabric | D13: 0.05 | E13: 400 | F13: 1300 | G13: 0.85 | H13: 0.5 | I13: 2 | J13: =AVERAGE(H13,I13) -> 1.25 | K13: =(J13/1000)/D13 -> 0.025 | L13: Low (unless treated) | M13: Low | N13: =IF(E13<200,"Light",IF(E13<1000,"Medium","Heavy")) -> Medium | O13: Low | P13: No | Q13: Partial | R13: Partial | S13: Yes | T13: Extremely lightweight, fast to deploy, low cost | U13: Negligible insulation alone, needs liner/PCM layer for cold climates, short lifespan | V13: SYNTHETIC/REFERENCE - typical values at the level of standard engineering literature (ASHRAE Fundamentals-type ranges); validate against manufacturer datasheets or measured lab data before final use.
... A21: M20 | B21: High-density fiberglass batt (cold-grade) | C21: Insulation | D21: 0.033 | E21: 48 | F21: 840 | G21: 0.9 | H21: 75 | I21: 200 | J21: =AVERAGE(H21,I21) -> 137.5 | K21: =(J21/1000)/D21 -> 4.1666667 | L21: Low-Medium | M21: Medium | N21: =IF(E21<200,"Light",IF(E21<1000,"Medium","Heavy")) -> Light | O21: Medium | P21: Yes | Q21: Partial | R21: No | S21: Partial | T21: Denser batt gives improved R-value per thickness vs standard fiberglass | U21: Same general moisture sensitivity as other batt insulations | V21: SYNTHETIC/REFERENCE - typical values at the level of standard engineering literature (ASHRAE Fundamentals-type ranges); validate against manufacturer datasheets or measured lab data before final use.

Sheet Shelter_Design
A1: Design_ID | B1: Climate_Archetype | C1: Shelter_Length_m | D1: Shelter_Width_m | E1: Shelter_Height_m | F1: Floor_Area_m2 | G1: Volume_m3 | H1: Orientation | I1: Wall_Material_ID | J1: Roof_Material_ID | K1: Floor_Material_ID | L1: Insulation_Material_ID | M1: Wall_Thickness_mm | N1: Roof_Thickness_mm | O1: Insulation_Thickness_mm | P1: Window_Opening_Area_m2 | Q1: Gross_Wall_Area_m2 | R1: Net_Wall_Area_m2 | S1: Opening_to_Wall_Ratio | T1: Ventilation_Type | U1: Number_of_Openings | V1: Shading_Type | W1: Roof_Type | X1: Roof_Reflectivity_Albedo | Y1: Number_of_Occupants | Z1: Activity_Level | AA1: Clothing_Level_clo | AB1: Shelter_Usage_Duration_hrs | AC1: Data_Source_Label
A2: D01 | B2: Cold / high-altitude | C2: 3 | D2: 3 | E2: 2.4 | F2: =C2*D2 -> 9 | G2: =C2*D2*E2 -> 21.6 | H2: South-facing (maximise winter solar gain) | I2: M06 | J2: M16 | K2: M01 | L2: M11 | M2: 150 | N2: 100 | O2: 100 | P2: 1.2 | Q2: =2*(C2+D2)*E2 -> 28.8 | R2: =Q2-P2 -> 27.6 | S2: =P2/Q2 -> 0.041666667 | T2: Minimal / sealed (winter-optimised) | U2: 2 | V2: None (maximise solar gain) | W2: Insulated flat/low-slope | X2: 0.3 | Y2: 2 | Z2: Resting / sleeping | AA2: 1.75 | AB2: 2160 | AC2: SYNTHETIC - prototype design configurations chosen by the team to span each climate archetype; not measurements of an existing built structure.
A3: D02 | B3: Cold / high-altitude | C3: 5 | D3: 4 | E3: 2.6 | F3: =C3*D3 -> 20 | G3: =C3*D3*E3 -> 52 | H3: South-facing (maximise winter solar gain) | I3: M06 | J3: M16 | K3: M01 | L3: M11 | M3: 150 | N3: 100 | O3: 100 | P3: 1.8 | Q3: =2*(C3+D3)*E3 -> 46.8 | R3: =Q3-P3 -> 45 | S3: =P3/Q3 -> 0.038461538 | T3: Minimal / sealed (winter-optimised) | U3: 2 | V3: None (maximise solar gain) | W3: Insulated flat/low-slope | X3: 0.3 | Y3: 5 | Z3: Resting / sleeping | AA3: 1.75 | AB3: 2160 | AC3: SYNTHETIC - prototype design configurations chosen by the team to span each climate archetype; not measurements of an existing built structure.
A4: D03 | B4: Cold / high-altitude | C4: 3 | D4: 3 | E4: 2.4 | F4: =C4*D4 -> 9 | G4: =C4*D4*E4 -> 21.6 | H4: South-facing (maximise winter solar gain) | I4: M06 | J4: M16 | K4: M01 | L4: M09 | M4: 150 | N4: 100 | O4: 150 | P4: 1.2 | Q4: =2*(C4+D4)*E4 -> 28.8 | R4: =Q4-P4 -> 27.6 | S4: =P4/Q4 -> 0.041666667 | T4: Minimal / sealed (winter-optimised) | U4: 2 | V4: None (maximise solar gain) | W4: Insulated flat/low-slope | X4: 0.3 | Y4: 2 | Z4: Resting / sleeping | AA4: 1.75 | AB4: 2160 | AC4: SYNTHETIC - prototype design configurations chosen by the team to span each climate archetype; not measurements of an existing built structure.
A5: D04 | B5: Cold / high-altitude | C5: 5 | D5: 4 | E5: 2.6 | F5: =C5*D5 -> 20 | G5: =C5*D5*E5 -> 52 | H5: South-facing (maximise winter solar gain) | I5: M06 | J5: M16 | K5: M01 | L5: M09 | M5: 150 | N5: 100 | O5: 150 | P5: 1.8 | Q5: =2*(C5+D5)*E5 -> 46.8 | R5: =Q5-P5 -> 45 | S5: =P5/Q5 -> 0.038461538 | T5: Minimal / sealed (winter-optimised) | U5: 2 | V5: None (maximise solar gain) | W5: Insulated flat/low-slope | X5: 0.3 | Y5: 5 | Z5: Resting / sleeping | AA5: 1.75 | AB5: 2160 | AC5: SYNTHETIC - prototype design configurations chosen by the team to span each climate archetype; not measurements of an existing built structure.
A6: D05 | B6: Cold / high-altitude | C6: 3 | D6: 3 | E6: 2.4 | F6: =C6*D6 -> 9 | G6: =C6*D6*E6 -> 21.6 | H6: South-facing (maximise winter solar gain) | I6: M15 | J6: M16 | K6: M01 | L6: M11 | M6: 250 | N6: 100 | O6: 100 | P6: 1.2 | Q6: =2*(C6+D6)*E6 -> 28.8 | R6: =Q6-P6 -> 27.6 | S6: =P6/Q6 -> 0.041666667 | T6: Minimal / sealed (winter-optimised) | U6: 2 | V6: None (maximise solar gain) | W6: Insulated flat/low-slope | X6: 0.3 | Y6: 2 | Z6: Resting / sleeping | AA6: 1.75 | AB6: 2160 | AC6: SYNTHETIC - prototype design configurations chosen by the team to span each climate archetype; not measurements of an existing built structure.
A7: D06 | B7: Cold / high-altitude | C7: 5 | D7: 4 | E7: 2.6 | F7: =C7*D7 -> 20 | G7: =C7*D7*E7 -> 52 | H7: South-facing (maximise winter solar gain) | I7: M15 | J7: M16 | K7: M01 | L7: M11 | M7: 250 | N7: 100 | O7: 100 | P7: 1.8 | Q7: =2*(C7+D7)*E7 -> 46.8 | R7: =Q7-P7 -> 45 | S7: =P7/Q7 -> 0.038461538 | T7: Minimal / sealed (winter-optimised) | U7: 2 | V7: None (maximise solar gain) | W7: Insulated flat/low-slope | X7: 0.3 | Y7: 5 | Z7: Resting / sleeping | AA7: 1.75 | AB7: 2160 | AC7: SYNTHETIC - prototype design configurations chosen by the team to span each climate archetype; not measurements of an existing built structure.
A8: D07 | B8: Cold / high-altitude | C8: 3 | D8: 3 | E8: 2.4 | F8: =C8*D8 -> 9 | G8: =C8*D8*E8 -> 21.6 | H8: South-facing (maximise winter solar gain) | I8: M15 | J8: M16 | K8: M01 | L8: M09 | M8: 250 | N8: 100 | O8: 150 | P8: 1.2 | Q8: =2*(C8+D8)*E8 -> 28.8 | R8: =Q8-P8 -> 27.6 | S8: =P8/Q8 -> 0.041666667 | T8: Minimal / sealed (winter-optimised) | U8: 2 | V8: None (maximise solar gain) | W8: Insulated flat/low-slope | X8: 0.3 | Y8: 2 | Z8: Resting / sleeping | AA8: 1.75 | AB8: 2160 | AC8: SYNTHETIC - prototype design configurations chosen by the team to span each climate archetype; not measurements of an existing built structure.
A9: D08 | B9: Cold / high-altitude | C9: 5 | D9: 4 | E9: 2.6 | F9: =C9*D9 -> 20 | G9: =C9*D9*E9 -> 52 | H9: South-facing (maximise winter solar gain) | I9: M15 | J9: M16 | K9: M01 | L9: M09 | M9: 250 | N9: 100 | O9: 150 | P9: 1.8 | Q9: =2*(C9+D9)*E9 -> 46.8 | R9: =Q9-P9 -> 45 | S9: =P9/Q9 -> 0.038461538 | T9: Minimal / sealed (winter-optimised) | U9: 2 | V9: None (maximise solar gain) | W9: Insulated flat/low-slope | X9: 0.3 | Y9: 5 | Z9: Resting / sleeping | AA9: 1.75 | AB9: 2160 | AC9: SYNTHETIC - prototype design configurations chosen by the team to span each climate archetype; not measurements of an existing built structure.
A10: D09 | B10: Hot-dry | C10: 3 | D10: 3.5 | E10: 2.6 | F10: =C10*D10 -> 10.5 | G10: =C10*D10*E10 -> 27.3 | H10: North-South long axis (minimise east/west solar wall exposure) | I10: M02 | J10: M19 | K10: M02 | L10: None | M10: 230 | N10: 1 | O10: 0 | P10: 1 | Q10: =2*(C10+D10)*E10 -> 33.8 | R10: =Q10-P10 -> 32.8 | S10: =P10/Q10 -> 0.029585799 | T10: Night ventilation, sealed by day | U10: 3 | V10: Overhangs / verandah shading | W10: Reflective sloped | X10: 0.65 | Y10: 2 | Z10: Light | AA10: 0.5 | AB10: 2160 | AC10: SYNTHETIC - prototype design configurations chosen by the team to span each climate archetype; not measurements of an existing built structure.
A11: D10 | B11: Hot-dry | C11: 5 | D11: 4.5 | E11: 2.8 | F11: =C11*D11 -> 22.5 | G11: =C11*D11*E11 -> 63 | H11: North-South long axis (minimise east/west solar wall exposure) | I11: M02 | J11: M19 | K11: M02 | L11: None | M11: 230 | N11: 1 | O11: 0 | P11: 1.6 | Q11: =2*(C11+D11)*E11 -> 53.2 | R11: =Q11-P11 -> 51.6 | S11: =P11/Q11 -> 0.030075188 | T11: Night ventilation, sealed by day | U11: 3 | V11: Overhangs / verandah shading | W11: Reflective sloped | X11: 0.65 | Y11: 5 | Z11: Light | AA11: 0.5 | AB11: 2160 | AC11: SYNTHETIC - prototype design configurations chosen by the team to span each climate archetype; not measurements of an existing built structure.
A12: D11 | B12: Hot-dry | C12: 3 | D12: 3.5 | E12: 2.6 | F12: =C12*D12 -> 10.5 | G12: =C12*D12*E12 -> 27.3 | H12: North-South long axis (minimise east/west solar wall exposure) | I12: M02 | J12: M19 | K12: M02 | L12: M08 | M12: 230 | N12: 1 | O12: 30 | P12: 1 | Q12: =2*(C12+D12)*E12 -> 33.8 | R12: =Q12-P12 -> 32.8 | S12: =P12/Q12 -> 0.029585799 | T12: Night ventilation, sealed by day | U12: 3 | V12: Overhangs / verandah shading | W12: Reflective sloped | X12: 0.65 | Y12: 2 | Z12: Light | AA12: 0.5 | AB12: 2160 | AC12: SYNTHETIC - prototype design configurations chosen by the team to span each climate archetype; not measurements of an existing built structure.
A13: D12 | B13: Hot-dry | C13: 5 | D13: 4.5 | E13: 2.8 | F13: =C13*D13 -> 22.5 | G13: =C13*D13*E13 -> 63 | H13: North-South long axis (minimise east/west solar wall exposure) | I13: M02 | J13: M19 | K13: M02 | L13: M08 | M13: 230 | N13: 1 | O13: 30 | P13: 1.6 | Q13: =2*(C13+D13)*E13 -> 53.2 | R13: =Q13-P13 -> 51.6 | S13: =P13/Q13 -> 0.030075188 | T13: Night ventilation, sealed by day | U13: 3 | V13: Overhangs / verandah shading | W13: Reflective sloped | X13: 0.65 | Y13: 5 | Z13: Light | AA13: 0.5 | AB13: 2160 | AC13: SYNTHETIC - prototype design configurations chosen by the team to span each climate archetype; not measurements of an existing built structure.
... A41: D40 | B41: Emergency / temporary | C41: 4 | D41: 3 | E41: 2.3 | F41: =C41*D41 -> 12 | G41: =C41*D41*E41 -> 27.6 | H41: Variable (rapid deployment, orientation not always controllable) | I41: M03+M12 | J41: M03+M12 | K41: M13 | L41: M07 | M41: 2 | N41: 2 | O41: 25 | P41: 1 | Q41: =2*(C41+D41)*E41 -> 32.2 | R41: =Q41-P41 -> 31.2 | S41: =P41/Q41 -> 0.031055901 | T41: Flap / vent openings | U41: 2 | V41: None / minimal (temporary deployment) | W41: Fabric / lightweight | X41: 0.4 | Y41: 4 | Z41: Light-moderate | AA41: 1 | AB41: 500 | AC41: SYNTHETIC - prototype design configurations chosen by the team to span each climate archetype; not measurements of an existing built structure.

Sheet Combined_Scenarios
A1: Scenario_ID | B1: Design_ID | C1: Climate_Archetype | D1: Match_Type | E1: Location | F1: Month | G1: Location_Month_Key | H1: Outdoor_Temperature_C | I1: Relative_Humidity_pct | J1: Wind_Speed_ms | K1: Solar_Radiation_Wm2 | L1: Rainfall_mm | M1: Wall_Material_ID | N1: Wall_k_WmK | O1: Wall_Thickness_mm | P1: Insulation_Material_ID | Q1: Insulation_k_WmK | R1: Insulation_Thickness_mm | S1: Wall_R_m2KW | T1: Insulation_R_m2KW | U1: Air_Film_R_m2KW | V1: Total_R_m2KW | W1: U_value_Wm2K | X1: Net_Wall_Area_m2 | Y1: Window_Opening_Area_m2 | Z1: Volume_m3 | AA1: Opening_to_Wall_Ratio | AB1: Number_of_Occupants | AC1: Activity_Level | AD1: Clothing_Level_clo | AE1: Data_Source_Label
A2: S001 | B2: D01 | C2: Cold / high-altitude | D2: Matched | E2: Leh | F2: January | G2: =E2&"-"&F2 -> Leh-January | H2: =INDEX(Weather_Data!$K$2:$K$73,MATCH($G2,Weather_Data!$J$2:$J$73,0)) -> -8 | I2: =INDEX(Weather_Data!$L$2:$L$73,MATCH($G2,Weather_Data!$J$2:$J$73,0)) -> 25 | J2: =INDEX(Weather_Data!$M$2:$M$73,MATCH($G2,Weather_Data!$J$2:$J$73,0)) -> 2 | K2: =INDEX(Weather_Data!$P$2:$P$73,MATCH($G2,Weather_Data!$J$2:$J$73,0)) -> 166.66667 | L2: =INDEX(Weather_Data!$Q$2:$Q$73,MATCH($G2,Weather_Data!$J$2:$J$73,0)) -> 5 | M2: =INDEX(Shelter_Design!$I$2:$I$41,MATCH($B2,Shelter_Design!$A$2:$A$41,0)) -> M06 | N2: =IFERROR(INDEX(Material_Properties!$D$2:$D$21,MATCH(M2,Material_Properties!$A$2:$A$21,0)),1) -> 0.14 | O2: =INDEX(Shelter_Design!$M$2:$M$41,MATCH($B2,Shelter_Design!$A$2:$A$41,0)) -> 150 | P2: =INDEX(Shelter_Design!$L$2:$L$41,MATCH($B2,Shelter_Design!$A$2:$A$41,0)) -> M11 | Q2: =IF(P2="None",0,IFERROR(INDEX(Material_Properties!$D$2:$D$21,MATCH(P2,Material_Properties!$A$2:$A$21,0)),0)) -> 0.025 | R2: =INDEX(Shelter_Design!$O$2:$O$41,MATCH($B2,Shelter_Design!$A$2:$A$41,0)) -> 100 | S2: =(O2/1000)/N2 -> 1.0714286 | T2: =IF(OR(P2="None",Q2=0),0,(R2/1000)/Q2) -> 4 | U2: 0.17 | V2: =S2+T2+U2 -> 5.2414286 | W2: =1/V2 -> 0.19078768 | X2: =INDEX(Shelter_Design!$R$2:$R$41,MATCH($B2,Shelter_Design!$A$2:$A$41,0)) -> 27.6 | Y2: =INDEX(Shelter_Design!$P$2:$P$41,MATCH($B2,Shelter_Design!$A$2:$A$41,0)) -> 1.2 | Z2: =INDEX(Shelter_Design!$G$2:$G$41,MATCH($B2,Shelter_Design!$A$2:$A$41,0)) -> 21.6 | AA2: =INDEX(Shelter_Design!$S$2:$S$41,MATCH($B2,Shelter_Design!$A$2:$A$41,0)) -> 0.041666667 | AB2: =INDEX(Shelter_Design!$Y$2:$Y$41,MATCH($B2,Shelter_Design!$A$2:$A$41,0)) -> 2 | AC2: =INDEX(Shelter_Design!$Z$2:$Z$41,MATCH($B2,Shelter_Design!$A$2:$A$41,0)) -> Resting / sleeping | AD2: =INDEX(Shelter_Design!$AA$2:$AA$41,MATCH($B2,Shelter_Design!$A$2:$A$41,0)) -> 1.75 | AE2: SYNTHETIC - scenario built by pairing a prototype shelter design with representative monthly climatology; not a record of a real, physically deployed shelter.
A3: S002 | B3: D01 | C3: Cold / high-altitude | D3: Matched | E3: Leh | F3: April | G3: =E3&"-"&F3 -> Leh-April | H3: =INDEX(Weather_Data!$K$2:$K$73,MATCH($G3,Weather_Data!$J$2:$J$73,0)) -> 7 | I3: =INDEX(Weather_Data!$L$2:$L$73,MATCH($G3,Weather_Data!$J$2:$J$73,0)) -> 30 | J3: =INDEX(Weather_Data!$M$2:$M$73,MATCH($G3,Weather_Data!$J$2:$J$73,0)) -> 4 | K3: =INDEX(Weather_Data!$P$2:$P$73,MATCH($G3,Weather_Data!$J$2:$J$73,0)) -> 270.83333 | L3: =INDEX(Weather_Data!$Q$2:$Q$73,MATCH($G3,Weather_Data!$J$2:$J$73,0)) -> 10 | M3: =INDEX(Shelter_Design!$I$2:$I$41,MATCH($B3,Shelter_Design!$A$2:$A$41,0)) -> M06 | N3: =IFERROR(INDEX(Material_Properties!$D$2:$D$21,MATCH(M3,Material_Properties!$A$2:$A$21,0)),1) -> 0.14 | O3: =INDEX(Shelter_Design!$M$2:$M$41,MATCH($B3,Shelter_Design!$A$2:$A$41,0)) -> 150 | P3: =INDEX(Shelter_Design!$L$2:$L$41,MATCH($B3,Shelter_Design!$A$2:$A$41,0)) -> M11 | Q3: =IF(P3="None",0,IFERROR(INDEX(Material_Properties!$D$2:$D$21,MATCH(P3,Material_Properties!$A$2:$A$21,0)),0)) -> 0.025 | R3: =INDEX(Shelter_Design!$O$2:$O$41,MATCH($B3,Shelter_Design!$A$2:$A$41,0)) -> 100 | S3: =(O3/1000)/N3 -> 1.0714286 | T3: =IF(OR(P3="None",Q3=0),0,(R3/1000)/Q3) -> 4 | U3: 0.17 | V3: =S3+T3+U3 -> 5.2414286 | W3: =1/V3 -> 0.19078768 | X3: =INDEX(Shelter_Design!$R$2:$R$41,MATCH($B3,Shelter_Design!$A$2:$A$41,0)) -> 27.6 | Y3: =INDEX(Shelter_Design!$P$2:$P$41,MATCH($B3,Shelter_Design!$A$2:$A$41,0)) -> 1.2 | Z3: =INDEX(Shelter_Design!$G$2:$G$41,MATCH($B3,Shelter_Design!$A$2:$A$41,0)) -> 21.6 | AA3: =INDEX(Shelter_Design!$S$2:$S$41,MATCH($B3,Shelter_Design!$A$2:$A$41,0)) -> 0.041666667 | AB3: =INDEX(Shelter_Design!$Y$2:$Y$41,MATCH($B3,Shelter_Design!$A$2:$A$41,0)) -> 2 | AC3: =INDEX(Shelter_Design!$Z$2:$Z$41,MATCH($B3,Shelter_Design!$A$2:$A$41,0)) -> Resting / sleeping | AD3: =INDEX(Shelter_Design!$AA$2:$AA$41,MATCH($B3,Shelter_Design!$A$2:$A$41,0)) -> 1.75 | AE3: SYNTHETIC - scenario built by pairing a prototype shelter design with representative monthly climatology; not a record of a real, physically deployed shelter.
A4: S003 | B4: D01 | C4: Cold / high-altitude | D4: Matched | E4: Leh | F4: July | G4: =E4&"-"&F4 -> Leh-July | H4: =INDEX(Weather_Data!$K$2:$K$73,MATCH($G4,Weather_Data!$J$2:$J$73,0)) -> 19 | I4: =INDEX(Weather_Data!$L$2:$L$73,MATCH($G4,Weather_Data!$J$2:$J$73,0)) -> 38 | J4: =INDEX(Weather_Data!$M$2:$M$73,MATCH($G4,Weather_Data!$J$2:$J$73,0)) -> 3 | K4: =INDEX(Weather_Data!$P$2:$P$73,MATCH($G4,Weather_Data!$J$2:$J$73,0)) -> 283.33333 | L4: =INDEX(Weather_Data!$Q$2:$Q$73,MATCH($G4,Weather_Data!$J$2:$J$73,0)) -> 15 | M4: =INDEX(Shelter_Design!$I$2:$I$41,MATCH($B4,Shelter_Design!$A$2:$A$41,0)) -> M06 | N4: =IFERROR(INDEX(Material_Properties!$D$2:$D$21,MATCH(M4,Material_Properties!$A$2:$A$21,0)),1) -> 0.14 | O4: =INDEX(Shelter_Design!$M$2:$M$41,MATCH($B4,Shelter_Design!$A$2:$A$41,0)) -> 150 | P4: =INDEX(Shelter_Design!$L$2:$L$41,MATCH($B4,Shelter_Design!$A$2:$A$41,0)) -> M11 | Q4: =IF(P4="None",0,IFERROR(INDEX(Material_Properties!$D$2:$D$21,MATCH(P4,Material_Properties!$A$2:$A$21,0)),0)) -> 0.025 | R4: =INDEX(Shelter_Design!$O$2:$O$41,MATCH($B4,Shelter_Design!$A$2:$A$41,0)) -> 100 | S4: =(O4/1000)/N4 -> 1.0714286 | T4: =IF(OR(P4="None",Q4=0),0,(R4/1000)/Q4) -> 4 | U4: 0.17 | V4: =S4+T4+U4 -> 5.2414286 | W4: =1/V4 -> 0.19078768 | X4: =INDEX(Shelter_Design!$R$2:$R$41,MATCH($B4,Shelter_Design!$A$2:$A$41,0)) -> 27.6 | Y4: =INDEX(Shelter_Design!$P$2:$P$41,MATCH($B4,Shelter_Design!$A$2:$A$41,0)) -> 1.2 | Z4: =INDEX(Shelter_Design!$G$2:$G$41,MATCH($B4,Shelter_Design!$A$2:$A$41,0)) -> 21.6 | AA4: =INDEX(Shelter_Design!$S$2:$S$41,MATCH($B4,Shelter_Design!$A$2:$A$41,0)) -> 0.041666667 | AB4: =INDEX(Shelter_Design!$Y$2:$Y$41,MATCH($B4,Shelter_Design!$A$2:$A$41,0)) -> 2 | AC4: =INDEX(Shelter_Design!$Z$2:$Z$41,MATCH($B4,Shelter_Design!$A$2:$A$41,0)) -> Resting / sleeping | AD4: =INDEX(Shelter_Design!$AA$2:$AA$41,MATCH($B4,Shelter_Design!$A$2:$A$41,0)) -> 1.75 | AE4: SYNTHETIC - scenario built by pairing a prototype shelter design with representative monthly climatology; not a record of a real, physically deployed shelter.
A5: S004 | B5: D01 | C5: Cold / high-altitude | D5: Matched | E5: Leh | F5: September | G5: =E5&"-"&F5 -> Leh-September | H5: =INDEX(Weather_Data!$K$2:$K$73,MATCH($G5,Weather_Data!$J$2:$J$73,0)) -> 14 | I5: =INDEX(Weather_Data!$L$2:$L$73,MATCH($G5,Weather_Data!$J$2:$J$73,0)) -> 35 | J5: =INDEX(Weather_Data!$M$2:$M$73,MATCH($G5,Weather_Data!$J$2:$J$73,0)) -> 3 | K5: =INDEX(Weather_Data!$P$2:$P$73,MATCH($G5,Weather_Data!$J$2:$J$73,0)) -> 250 | L5: =INDEX(Weather_Data!$Q$2:$Q$73,MATCH($G5,Weather_Data!$J$2:$J$73,0)) -> 8 | M5: =INDEX(Shelter_Design!$I$2:$I$41,MATCH($B5,Shelter_Design!$A$2:$A$41,0)) -> M06 | N5: =IFERROR(INDEX(Material_Properties!$D$2:$D$21,MATCH(M5,Material_Properties!$A$2:$A$21,0)),1) -> 0.14 | O5: =INDEX(Shelter_Design!$M$2:$M$41,MATCH($B5,Shelter_Design!$A$2:$A$41,0)) -> 150 | P5: =INDEX(Shelter_Design!$L$2:$L$41,MATCH($B5,Shelter_Design!$A$2:$A$41,0)) -> M11 | Q5: =IF(P5="None",0,IFERROR(INDEX(Material_Properties!$D$2:$D$21,MATCH(P5,Material_Properties!$A$2:$A$21,0)),0)) -> 0.025 | R5: =INDEX(Shelter_Design!$O$2:$O$41,MATCH($B5,Shelter_Design!$A$2:$A$41,0)) -> 100 | S5: =(O5/1000)/N5 -> 1.0714286 | T5: =IF(OR(P5="None",Q5=0),0,(R5/1000)/Q5) -> 4 | U5: 0.17 | V5: =S5+T5+U5 -> 5.2414286 | W5: =1/V5 -> 0.19078768 | X5: =INDEX(Shelter_Design!$R$2:$R$41,MATCH($B5,Shelter_Design!$A$2:$A$41,0)) -> 27.6 | Y5: =INDEX(Shelter_Design!$P$2:$P$41,MATCH($B5,Shelter_Design!$A$2:$A$41,0)) -> 1.2 | Z5: =INDEX(Shelter_Design!$G$2:$G$41,MATCH($B5,Shelter_Design!$A$2:$A$41,0)) -> 21.6 | AA5: =INDEX(Shelter_Design!$S$2:$S$41,MATCH($B5,Shelter_Design!$A$2:$A$41,0)) -> 0.041666667 | AB5: =INDEX(Shelter_Design!$Y$2:$Y$41,MATCH($B5,Shelter_Design!$A$2:$A$41,0)) -> 2 | AC5: =INDEX(Shelter_Design!$Z$2:$Z$41,MATCH($B5,Shelter_Design!$A$2:$A$41,0)) -> Resting / sleeping | AD5: =INDEX(Shelter_Design!$AA$2:$AA$41,MATCH($B5,Shelter_Design!$A$2:$A$41,0)) -> 1.75 | AE5: SYNTHETIC - scenario built by pairing a prototype shelter design with representative monthly climatology; not a record of a real, physically deployed shelter.
A6: S005 | B6: D01 | C6: Cold / high-altitude | D6: Matched | E6: Leh | F6: November | G6: =E6&"-"&F6 -> Leh-November | H6: =INDEX(Weather_Data!$K$2:$K$73,MATCH($G6,Weather_Data!$J$2:$J$73,0)) -> -1 | I6: =INDEX(Weather_Data!$L$2:$L$73,MATCH($G6,Weather_Data!$J$2:$J$73,0)) -> 27 | J6: =INDEX(Weather_Data!$M$2:$M$73,MATCH($G6,Weather_Data!$J$2:$J$73,0)) -> 2 | K6: =INDEX(Weather_Data!$P$2:$P$73,MATCH($G6,Weather_Data!$J$2:$J$73,0)) -> 175 | L6: =INDEX(Weather_Data!$Q$2:$Q$73,MATCH($G6,Weather_Data!$J$2:$J$73,0)) -> 2 | M6: =INDEX(Shelter_Design!$I$2:$I$41,MATCH($B6,Shelter_Design!$A$2:$A$41,0)) -> M06 | N6: =IFERROR(INDEX(Material_Properties!$D$2:$D$21,MATCH(M6,Material_Properties!$A$2:$A$21,0)),1) -> 0.14 | O6: =INDEX(Shelter_Design!$M$2:$M$41,MATCH($B6,Shelter_Design!$A$2:$A$41,0)) -> 150 | P6: =INDEX(Shelter_Design!$L$2:$L$41,MATCH($B6,Shelter_Design!$A$2:$A$41,0)) -> M11 | Q6: =IF(P6="None",0,IFERROR(INDEX(Material_Properties!$D$2:$D$21,MATCH(P6,Material_Properties!$A$2:$A$21,0)),0)) -> 0.025 | R6: =INDEX(Shelter_Design!$O$2:$O$41,MATCH($B6,Shelter_Design!$A$2:$A$41,0)) -> 100 | S6: =(O6/1000)/N6 -> 1.0714286 | T6: =IF(OR(P6="None",Q6=0),0,(R6/1000)/Q6) -> 4 | U6: 0.17 | V6: =S6+T6+U6 -> 5.2414286 | W6: =1/V6 -> 0.19078768 | X6: =INDEX(Shelter_Design!$R$2:$R$41,MATCH($B6,Shelter_Design!$A$2:$A$41,0)) -> 27.6 | Y6: =INDEX(Shelter_Design!$P$2:$P$41,MATCH($B6,Shelter_Design!$A$2:$A$41,0)) -> 1.2 | Z6: =INDEX(Shelter_Design!$G$2:$G$41,MATCH($B6,Shelter_Design!$A$2:$A$41,0)) -> 21.6 | AA6: =INDEX(Shelter_Design!$S$2:$S$41,MATCH($B6,Shelter_Design!$A$2:$A$41,0)) -> 0.041666667 | AB6: =INDEX(Shelter_Design!$Y$2:$Y$41,MATCH($B6,Shelter_Design!$A$2:$A$41,0)) -> 2 | AC6: =INDEX(Shelter_Design!$Z$2:$Z$41,MATCH($B6,Shelter_Design!$A$2:$A$41,0)) -> Resting / sleeping | AD6: =INDEX(Shelter_Design!$AA$2:$AA$41,MATCH($B6,Shelter_Design!$A$2:$A$41,0)) -> 1.75 | AE6: SYNTHETIC - scenario built by pairing a prototype shelter design with representative monthly climatology; not a record of a real, physically deployed shelter.
A7: S006 | B7: D02 | C7: Cold / high-altitude | D7: Matched | E7: Leh | F7: January | G7: =E7&"-"&F7 -> Leh-January | H7: =INDEX(Weather_Data!$K$2:$K$73,MATCH($G7,Weather_Data!$J$2:$J$73,0)) -> -8 | I7: =INDEX(Weather_Data!$L$2:$L$73,MATCH($G7,Weather_Data!$J$2:$J$73,0)) -> 25 | J7: =INDEX(Weather_Data!$M$2:$M$73,MATCH($G7,Weather_Data!$J$2:$J$73,0)) -> 2 | K7: =INDEX(Weather_Data!$P$2:$P$73,MATCH($G7,Weather_Data!$J$2:$J$73,0)) -> 166.66667 | L7: =INDEX(Weather_Data!$Q$2:$Q$73,MATCH($G7,Weather_Data!$J$2:$J$73,0)) -> 5 | M7: =INDEX(Shelter_Design!$I$2:$I$41,MATCH($B7,Shelter_Design!$A$2:$A$41,0)) -> M06 | N7: =IFERROR(INDEX(Material_Properties!$D$2:$D$21,MATCH(M7,Material_Properties!$A$2:$A$21,0)),1) -> 0.14 | O7: =INDEX(Shelter_Design!$M$2:$M$41,MATCH($B7,Shelter_Design!$A$2:$A$41,0)) -> 150 | P7: =INDEX(Shelter_Design!$L$2:$L$41,MATCH($B7,Shelter_Design!$A$2:$A$41,0)) -> M11 | Q7: =IF(P7="None",0,IFERROR(INDEX(Material_Properties!$D$2:$D$21,MATCH(P7,Material_Properties!$A$2:$A$21,0)),0)) -> 0.025 | R7: =INDEX(Shelter_Design!$O$2:$O$41,MATCH($B7,Shelter_Design!$A$2:$A$41,0)) -> 100 | S7: =(O7/1000)/N7 -> 1.0714286 | T7: =IF(OR(P7="None",Q7=0),0,(R7/1000)/Q7) -> 4 | U7: 0.17 | V7: =S7+T7+U7 -> 5.2414286 | W7: =1/V7 -> 0.19078768 | X7: =INDEX(Shelter_Design!$R$2:$R$41,MATCH($B7,Shelter_Design!$A$2:$A$41,0)) -> 45 | Y7: =INDEX(Shelter_Design!$P$2:$P$41,MATCH($B7,Shelter_Design!$A$2:$A$41,0)) -> 1.8 | Z7: =INDEX(Shelter_Design!$G$2:$G$41,MATCH($B7,Shelter_Design!$A$2:$A$41,0)) -> 52 | AA7: =INDEX(Shelter_Design!$S$2:$S$41,MATCH($B7,Shelter_Design!$A$2:$A$41,0)) -> 0.038461538 | AB7: =INDEX(Shelter_Design!$Y$2:$Y$41,MATCH($B7,Shelter_Design!$A$2:$A$41,0)) -> 5 | AC7: =INDEX(Shelter_Design!$Z$2:$Z$41,MATCH($B7,Shelter_Design!$A$2:$A$41,0)) -> Resting / sleeping | AD7: =INDEX(Shelter_Design!$AA$2:$AA$41,MATCH($B7,Shelter_Design!$A$2:$A$41,0)) -> 1.75 | AE7: SYNTHETIC - scenario built by pairing a prototype shelter design with representative monthly climatology; not a record of a real, physically deployed shelter.
A8: S007 | B8: D02 | C8: Cold / high-altitude | D8: Matched | E8: Leh | F8: April | G8: =E8&"-"&F8 -> Leh-April | H8: =INDEX(Weather_Data!$K$2:$K$73,MATCH($G8,Weather_Data!$J$2:$J$73,0)) -> 7 | I8: =INDEX(Weather_Data!$L$2:$L$73,MATCH($G8,Weather_Data!$J$2:$J$73,0)) -> 30 | J8: =INDEX(Weather_Data!$M$2:$M$73,MATCH($G8,Weather_Data!$J$2:$J$73,0)) -> 4 | K8: =INDEX(Weather_Data!$P$2:$P$73,MATCH($G8,Weather_Data!$J$2:$J$73,0)) -> 270.83333 | L8: =INDEX(Weather_Data!$Q$2:$Q$73,MATCH($G8,Weather_Data!$J$2:$J$73,0)) -> 10 | M8: =INDEX(Shelter_Design!$I$2:$I$41,MATCH($B8,Shelter_Design!$A$2:$A$41,0)) -> M06 | N8: =IFERROR(INDEX(Material_Properties!$D$2:$D$21,MATCH(M8,Material_Properties!$A$2:$A$21,0)),1) -> 0.14 | O8: =INDEX(Shelter_Design!$M$2:$M$41,MATCH($B8,Shelter_Design!$A$2:$A$41,0)) -> 150 | P8: =INDEX(Shelter_Design!$L$2:$L$41,MATCH($B8,Shelter_Design!$A$2:$A$41,0)) -> M11 | Q8: =IF(P8="None",0,IFERROR(INDEX(Material_Properties!$D$2:$D$21,MATCH(P8,Material_Properties!$A$2:$A$21,0)),0)) -> 0.025 | R8: =INDEX(Shelter_Design!$O$2:$O$41,MATCH($B8,Shelter_Design!$A$2:$A$41,0)) -> 100 | S8: =(O8/1000)/N8 -> 1.0714286 | T8: =IF(OR(P8="None",Q8=0),0,(R8/1000)/Q8) -> 4 | U8: 0.17 | V8: =S8+T8+U8 -> 5.2414286 | W8: =1/V8 -> 0.19078768 | X8: =INDEX(Shelter_Design!$R$2:$R$41,MATCH($B8,Shelter_Design!$A$2:$A$41,0)) -> 45 | Y8: =INDEX(Shelter_Design!$P$2:$P$41,MATCH($B8,Shelter_Design!$A$2:$A$41,0)) -> 1.8 | Z8: =INDEX(Shelter_Design!$G$2:$G$41,MATCH($B8,Shelter_Design!$A$2:$A$41,0)) -> 52 | AA8: =INDEX(Shelter_Design!$S$2:$S$41,MATCH($B8,Shelter_Design!$A$2:$A$41,0)) -> 0.038461538 | AB8: =INDEX(Shelter_Design!$Y$2:$Y$41,MATCH($B8,Shelter_Design!$A$2:$A$41,0)) -> 5 | AC8: =INDEX(Shelter_Design!$Z$2:$Z$41,MATCH($B8,Shelter_Design!$A$2:$A$41,0)) -> Resting / sleeping | AD8: =INDEX(Shelter_Design!$AA$2:$AA$41,MATCH($B8,Shelter_Design!$A$2:$A$41,0)) -> 1.75 | AE8: SYNTHETIC - scenario built by pairing a prototype shelter design with representative monthly climatology; not a record of a real, physically deployed shelter.
A9: S008 | B9: D02 | C9: Cold / high-altitude | D9: Matched | E9: Leh | F9: July | G9: =E9&"-"&F9 -> Leh-July | H9: =INDEX(Weather_Data!$K$2:$K$73,MATCH($G9,Weather_Data!$J$2:$J$73,0)) -> 19 | I9: =INDEX(Weather_Data!$L$2:$L$73,MATCH($G9,Weather_Data!$J$2:$J$73,0)) -> 38 | J9: =INDEX(Weather_Data!$M$2:$M$73,MATCH($G9,Weather_Data!$J$2:$J$73,0)) -> 3 | K9: =INDEX(Weather_Data!$P$2:$P$73,MATCH($G9,Weather_Data!$J$2:$J$73,0)) -> 283.33333 | L9: =INDEX(Weather_Data!$Q$2:$Q$73,MATCH($G9,Weather_Data!$J$2:$J$73,0)) -> 15 | M9: =INDEX(Shelter_Design!$I$2:$I$41,MATCH($B9,Shelter_Design!$A$2:$A$41,0)) -> M06 | N9: =IFERROR(INDEX(Material_Properties!$D$2:$D$21,MATCH(M9,Material_Properties!$A$2:$A$21,0)),1) -> 0.14 | O9: =INDEX(Shelter_Design!$M$2:$M$41,MATCH($B9,Shelter_Design!$A$2:$A$41,0)) -> 150 | P9: =INDEX(Shelter_Design!$L$2:$L$41,MATCH($B9,Shelter_Design!$A$2:$A$41,0)) -> M11 | Q9: =IF(P9="None",0,IFERROR(INDEX(Material_Properties!$D$2:$D$21,MATCH(P9,Material_Properties!$A$2:$A$21,0)),0)) -> 0.025 | R9: =INDEX(Shelter_Design!$O$2:$O$41,MATCH($B9,Shelter_Design!$A$2:$A$41,0)) -> 100 | S9: =(O9/1000)/N9 -> 1.0714286 | T9: =IF(OR(P9="None",Q9=0),0,(R9/1000)/Q9) -> 4 | U9: 0.17 | V9: =S9+T9+U9 -> 5.2414286 | W9: =1/V9 -> 0.19078768 | X9: =INDEX(Shelter_Design!$R$2:$R$41,MATCH($B9,Shelter_Design!$A$2:$A$41,0)) -> 45 | Y9: =INDEX(Shelter_Design!$P$2:$P$41,MATCH($B9,Shelter_Design!$A$2:$A$41,0)) -> 1.8 | Z9: =INDEX(Shelter_Design!$G$2:$G$41,MATCH($B9,Shelter_Design!$A$2:$A$41,0)) -> 52 | AA9: =INDEX(Shelter_Design!$S$2:$S$41,MATCH($B9,Shelter_Design!$A$2:$A$41,0)) -> 0.038461538 | AB9: =INDEX(Shelter_Design!$Y$2:$Y$41,MATCH($B9,Shelter_Design!$A$2:$A$41,0)) -> 5 | AC9: =INDEX(Shelter_Design!$Z$2:$Z$41,MATCH($B9,Shelter_Design!$A$2:$A$41,0)) -> Resting / sleeping | AD9: =INDEX(Shelter_Design!$AA$2:$AA$41,MATCH($B9,Shelter_Design!$A$2:$A$41,0)) -> 1.75 | AE9: SYNTHETIC - scenario built by pairing a prototype shelter design with representative monthly climatology; not a record of a real, physically deployed shelter.
A10: S009 | B10: D02 | C10: Cold / high-altitude | D10: Matched | E10: Leh | F10: September | G10: =E10&"-"&F10 -> Leh-September | H10: =INDEX(Weather_Data!$K$2:$K$73,MATCH($G10,Weather_Data!$J$2:$J$73,0)) -> 14 | I10: =INDEX(Weather_Data!$L$2:$L$73,MATCH($G10,Weather_Data!$J$2:$J$73,0)) -> 35 | J10: =INDEX(Weather_Data!$M$2:$M$73,MATCH($G10,Weather_Data!$J$2:$J$73,0)) -> 3 | K10: =INDEX(Weather_Data!$P$2:$P$73,MATCH($G10,Weather_Data!$J$2:$J$73,0)) -> 250 | L10: =INDEX(Weather_Data!$Q$2:$Q$73,MATCH($G10,Weather_Data!$J$2:$J$73,0)) -> 8 | M10: =INDEX(Shelter_Design!$I$2:$I$41,MATCH($B10,Shelter_Design!$A$2:$A$41,0)) -> M06 | N10: =IFERROR(INDEX(Material_Properties!$D$2:$D$21,MATCH(M10,Material_Properties!$A$2:$A$21,0)),1) -> 0.14 | O10: =INDEX(Shelter_Design!$M$2:$M$41,MATCH($B10,Shelter_Design!$A$2:$A$41,0)) -> 150 | P10: =INDEX(Shelter_Design!$L$2:$L$41,MATCH($B10,Shelter_Design!$A$2:$A$41,0)) -> M11 | Q10: =IF(P10="None",0,IFERROR(INDEX(Material_Properties!$D$2:$D$21,MATCH(P10,Material_Properties!$A$2:$A$21,0)),0)) -> 0.025 | R10: =INDEX(Shelter_Design!$O$2:$O$41,MATCH($B10,Shelter_Design!$A$2:$A$41,0)) -> 100 | S10: =(O10/1000)/N10 -> 1.0714286 | T10: =IF(OR(P10="None",Q10=0),0,(R10/1000)/Q10) -> 4 | U10: 0.17 | V10: =S10+T10+U10 -> 5.2414286 | W10: =1/V10 -> 0.19078768 | X10: =INDEX(Shelter_Design!$R$2:$R$41,MATCH($B10,Shelter_Design!$A$2:$A$41,0)) -> 45 | Y10: =INDEX(Shelter_Design!$P$2:$P$41,MATCH($B10,Shelter_Design!$A$2:$A$41,0)) -> 1.8 | Z10: =INDEX(Shelter_Design!$G$2:$G$41,MATCH($B10,Shelter_Design!$A$2:$A$41,0)) -> 52 | AA10: =INDEX(Shelter_Design!$S$2:$S$41,MATCH($B10,Shelter_Design!$A$2:$A$41,0)) -> 0.038461538 | AB10: =INDEX(Shelter_Design!$Y$2:$Y$41,MATCH($B10,Shelter_Design!$A$2:$A$41,0)) -> 5 | AC10: =INDEX(Shelter_Design!$Z$2:$Z$41,MATCH($B10,Shelter_Design!$A$2:$A$41,0)) -> Resting / sleeping | AD10: =INDEX(Shelter_Design!$AA$2:$AA$41,MATCH($B10,Shelter_Design!$A$2:$A$41,0)) -> 1.75 | AE10: SYNTHETIC - scenario built by pairing a prototype shelter design with representative monthly climatology; not a record of a real, physically deployed shelter.
A11: S010 | B11: D02 | C11: Cold / high-altitude | D11: Matched | E11: Leh | F11: November | G11: =E11&"-"&F11 -> Leh-November | H11: =INDEX(Weather_Data!$K$2:$K$73,MATCH($G11,Weather_Data!$J$2:$J$73,0)) -> -1 | I11: =INDEX(Weather_Data!$L$2:$L$73,MATCH($G11,Weather_Data!$J$2:$J$73,0)) -> 27 | J11: =INDEX(Weather_Data!$M$2:$M$73,MATCH($G11,Weather_Data!$J$2:$J$73,0)) -> 2 | K11: =INDEX(Weather_Data!$P$2:$P$73,MATCH($G11,Weather_Data!$J$2:$J$73,0)) -> 175 | L11: =INDEX(Weather_Data!$Q$2:$Q$73,MATCH($G11,Weather_Data!$J$2:$J$73,0)) -> 2 | M11: =INDEX(Shelter_Design!$I$2:$I$41,MATCH($B11,Shelter_Design!$A$2:$A$41,0)) -> M06 | N11: =IFERROR(INDEX(Material_Properties!$D$2:$D$21,MATCH(M11,Material_Properties!$A$2:$A$21,0)),1) -> 0.14 | O11: =INDEX(Shelter_Design!$M$2:$M$41,MATCH($B11,Shelter_Design!$A$2:$A$41,0)) -> 150 | P11: =INDEX(Shelter_Design!$L$2:$L$41,MATCH($B11,Shelter_Design!$A$2:$A$41,0)) -> M11 | Q11: =IF(P11="None",0,IFERROR(INDEX(Material_Properties!$D$2:$D$21,MATCH(P11,Material_Properties!$A$2:$A$21,0)),0)) -> 0.025 | R11: =INDEX(Shelter_Design!$O$2:$O$41,MATCH($B11,Shelter_Design!$A$2:$A$41,0)) -> 100 | S11: =(O11/1000)/N11 -> 1.0714286 | T11: =IF(OR(P11="None",Q11=0),0,(R11/1000)/Q11) -> 4 | U11: 0.17 | V11: =S11+T11+U11 -> 5.2414286 | W11: =1/V11 -> 0.19078768 | X11: =INDEX(Shelter_Design!$R$2:$R$41,MATCH($B11,Shelter_Design!$A$2:$A$41,0)) -> 45 | Y11: =INDEX(Shelter_Design!$P$2:$P$41,MATCH($B11,Shelter_Design!$A$2:$A$41,0)) -> 1.8 | Z11: =INDEX(Shelter_Design!$G$2:$G$41,MATCH($B11,Shelter_Design!$A$2:$A$41,0)) -> 52 | AA11: =INDEX(Shelter_Design!$S$2:$S$41,MATCH($B11,Shelter_Design!$A$2:$A$41,0)) -> 0.038461538 | AB11: =INDEX(Shelter_Design!$Y$2:$Y$41,MATCH($B11,Shelter_Design!$A$2:$A$41,0)) -> 5 | AC11: =INDEX(Shelter_Design!$Z$2:$Z$41,MATCH($B11,Shelter_Design!$A$2:$A$41,0)) -> Resting / sleeping | AD11: =INDEX(Shelter_Design!$AA$2:$AA$41,MATCH($B11,Shelter_Design!$A$2:$A$41,0)) -> 1.75 | AE11: SYNTHETIC - scenario built by pairing a prototype shelter design with representative monthly climatology; not a record of a real, physically deployed shelter.
A12: S011 | B12: D03 | C12: Cold / high-altitude | D12: Matched | E12: Leh | F12: January | G12: =E12&"-"&F12 -> Leh-January | H12: =INDEX(Weather_Data!$K$2:$K$73,MATCH($G12,Weather_Data!$J$2:$J$73,0)) -> -8 | I12: =INDEX(Weather_Data!$L$2:$L$73,MATCH($G12,Weather_Data!$J$2:$J$73,0)) -> 25 | J12: =INDEX(Weather_Data!$M$2:$M$73,MATCH($G12,Weather_Data!$J$2:$J$73,0)) -> 2 | K12: =INDEX(Weather_Data!$P$2:$P$73,MATCH($G12,Weather_Data!$J$2:$J$73,0)) -> 166.66667 | L12: =INDEX(Weather_Data!$Q$2:$Q$73,MATCH($G12,Weather_Data!$J$2:$J$73,0)) -> 5 | M12: =INDEX(Shelter_Design!$I$2:$I$41,MATCH($B12,Shelter_Design!$A$2:$A$41,0)) -> M06 | N12: =IFERROR(INDEX(Material_Properties!$D$2:$D$21,MATCH(M12,Material_Properties!$A$2:$A$21,0)),1) -> 0.14 | O12: =INDEX(Shelter_Design!$M$2:$M$41,MATCH($B12,Shelter_Design!$A$2:$A$41,0)) -> 150 | P12: =INDEX(Shelter_Design!$L$2:$L$41,MATCH($B12,Shelter_Design!$A$2:$A$41,0)) -> M09 | Q12: =IF(P12="None",0,IFERROR(INDEX(Material_Properties!$D$2:$D$21,MATCH(P12,Material_Properties!$A$2:$A$21,0)),0)) -> 0.04 | R12: =INDEX(Shelter_Design!$O$2:$O$41,MATCH($B12,Shelter_Design!$A$2:$A$41,0)) -> 150 | S12: =(O12/1000)/N12 -> 1.0714286 | T12: =IF(OR(P12="None",Q12=0),0,(R12/1000)/Q12) -> 3.75 | U12: 0.17 | V12: =S12+T12+U12 -> 4.9914286 | W12: =1/V12 -> 0.20034345 | X12: =INDEX(Shelter_Design!$R$2:$R$41,MATCH($B12,Shelter_Design!$A$2:$A$41,0)) -> 27.6 | Y12: =INDEX(Shelter_Design!$P$2:$P$41,MATCH($B12,Shelter_Design!$A$2:$A$41,0)) -> 1.2 | Z12: =INDEX(Shelter_Design!$G$2:$G$41,MATCH($B12,Shelter_Design!$A$2:$A$41,0)) -> 21.6 | AA12: =INDEX(Shelter_Design!$S$2:$S$41,MATCH($B12,Shelter_Design!$A$2:$A$41,0)) -> 0.041666667 | AB12: =INDEX(Shelter_Design!$Y$2:$Y$41,MATCH($B12,Shelter_Design!$A$2:$A$41,0)) -> 2 | AC12: =INDEX(Shelter_Design!$Z$2:$Z$41,MATCH($B12,Shelter_Design!$A$2:$A$41,0)) -> Resting / sleeping | AD12: =INDEX(Shelter_Design!$AA$2:$AA$41,MATCH($B12,Shelter_Design!$A$2:$A$41,0)) -> 1.75 | AE12: SYNTHETIC - scenario built by pairing a prototype shelter design with representative monthly climatology; not a record of a real, physically deployed shelter.
A13: S012 | B13: D03 | C13: Cold / high-altitude | D13: Matched | E13: Leh | F13: April | G13: =E13&"-"&F13 -> Leh-April | H13: =INDEX(Weather_Data!$K$2:$K$73,MATCH($G13,Weather_Data!$J$2:$J$73,0)) -> 7 | I13: =INDEX(Weather_Data!$L$2:$L$73,MATCH($G13,Weather_Data!$J$2:$J$73,0)) -> 30 | J13: =INDEX(Weather_Data!$M$2:$M$73,MATCH($G13,Weather_Data!$J$2:$J$73,0)) -> 4 | K13: =INDEX(Weather_Data!$P$2:$P$73,MATCH($G13,Weather_Data!$J$2:$J$73,0)) -> 270.83333 | L13: =INDEX(Weather_Data!$Q$2:$Q$73,MATCH($G13,Weather_Data!$J$2:$J$73,0)) -> 10 | M13: =INDEX(Shelter_Design!$I$2:$I$41,MATCH($B13,Shelter_Design!$A$2:$A$41,0)) -> M06 | N13: =IFERROR(INDEX(Material_Properties!$D$2:$D$21,MATCH(M13,Material_Properties!$A$2:$A$21,0)),1) -> 0.14 | O13: =INDEX(Shelter_Design!$M$2:$M$41,MATCH($B13,Shelter_Design!$A$2:$A$41,0)) -> 150 | P13: =INDEX(Shelter_Design!$L$2:$L$41,MATCH($B13,Shelter_Design!$A$2:$A$41,0)) -> M09 | Q13: =IF(P13="None",0,IFERROR(INDEX(Material_Properties!$D$2:$D$21,MATCH(P13,Material_Properties!$A$2:$A$21,0)),0)) -> 0.04 | R13: =INDEX(Shelter_Design!$O$2:$O$41,MATCH($B13,Shelter_Design!$A$2:$A$41,0)) -> 150 | S13: =(O13/1000)/N13 -> 1.0714286 | T13: =IF(OR(P13="None",Q13=0),0,(R13/1000)/Q13) -> 3.75 | U13: 0.17 | V13: =S13+T13+U13 -> 4.9914286 | W13: =1/V13 -> 0.20034345 | X13: =INDEX(Shelter_Design!$R$2:$R$41,MATCH($B13,Shelter_Design!$A$2:$A$41,0)) -> 27.6 | Y13: =INDEX(Shelter_Design!$P$2:$P$41,MATCH($B13,Shelter_Design!$A$2:$A$41,0)) -> 1.2 | Z13: =INDEX(Shelter_Design!$G$2:$G$41,MATCH($B13,Shelter_Design!$A$2:$A$41,0)) -> 21.6 | AA13: =INDEX(Shelter_Design!$S$2:$S$41,MATCH($B13,Shelter_Design!$A$2:$A$41,0)) -> 0.041666667 | AB13: =INDEX(Shelter_Design!$Y$2:$Y$41,MATCH($B13,Shelter_Design!$A$2:$A$41,0)) -> 2 | AC13: =INDEX(Shelter_Design!$Z$2:$Z$41,MATCH($B13,Shelter_Design!$A$2:$A$41,0)) -> Resting / sleeping | AD13: =INDEX(Shelter_Design!$AA$2:$AA$41,MATCH($B13,Shelter_Design!$A$2:$A$41,0)) -> 1.75 | AE13: SYNTHETIC - scenario built by pairing a prototype shelter design with representative monthly climatology; not a record of a real, physically deployed shelter.
... A229: S228 | B229: D16 | C229: Hot-dry | D229: Mismatched (stress test) | E229: Leh | F229: January | G229: =E229&"-"&F229 -> Leh-January | H229: =INDEX(Weather_Data!$K$2:$K$73,MATCH($G229,Weather_Data!$J$2:$J$73,0)) -> -8 | I229: =INDEX(Weather_Data!$L$2:$L$73,MATCH($G229,Weather_Data!$J$2:$J$73,0)) -> 25 | J229: =INDEX(Weather_Data!$M$2:$M$73,MATCH($G229,Weather_Data!$J$2:$J$73,0)) -> 2 | K229: =INDEX(Weather_Data!$P$2:$P$73,MATCH($G229,Weather_Data!$J$2:$J$73,0)) -> 166.66667 | L229: =INDEX(Weather_Data!$Q$2:$Q$73,MATCH($G229,Weather_Data!$J$2:$J$73,0)) -> 5 | M229: =INDEX(Shelter_Design!$I$2:$I$41,MATCH($B229,Shelter_Design!$A$2:$A$41,0)) -> M14 | N229: =IFERROR(INDEX(Material_Properties!$D$2:$D$21,MATCH(M229,Material_Properties!$A$2:$A$21,0)),1) -> 0.6 | O229: =INDEX(Shelter_Design!$M$2:$M$41,MATCH($B229,Shelter_Design!$A$2:$A$41,0)) -> 300 | P229: =INDEX(Shelter_Design!$L$2:$L$41,MATCH($B229,Shelter_Design!$A$2:$A$41,0)) -> M08 | Q229: =IF(P229="None",0,IFERROR(INDEX(Material_Properties!$D$2:$D$21,MATCH(P229,Material_Properties!$A$2:$A$21,0)),0)) -> 0.031 | R229: =INDEX(Shelter_Design!$O$2:$O$41,MATCH($B229,Shelter_Design!$A$2:$A$41,0)) -> 30 | S229: =(O229/1000)/N229 -> 0.5 | T229: =IF(OR(P229="None",Q229=0),0,(R229/1000)/Q229) -> 0.96774194 | U229: 0.17 | V229: =S229+T229+U229 -> 1.6377419 | W229: =1/V229 -> 0.61059681 | X229: =INDEX(Shelter_Design!$R$2:$R$41,MATCH($B229,Shelter_Design!$A$2:$A$41,0)) -> 51.6 | Y229: =INDEX(Shelter_Design!$P$2:$P$41,MATCH($B229,Shelter_Design!$A$2:$A$41,0)) -> 1.6 | Z229: =INDEX(Shelter_Design!$G$2:$G$41,MATCH($B229,Shelter_Design!$A$2:$A$41,0)) -> 63 | AA229: =INDEX(Shelter_Design!$S$2:$S$41,MATCH($B229,Shelter_Design!$A$2:$A$41,0)) -> 0.030075188 | AB229: =INDEX(Shelter_Design!$Y$2:$Y$41,MATCH($B229,Shelter_Design!$A$2:$A$41,0)) -> 5 | AC229: =INDEX(Shelter_Design!$Z$2:$Z$41,MATCH($B229,Shelter_Design!$A$2:$A$41,0)) -> Light | AD229: =INDEX(Shelter_Design!$AA$2:$AA$41,MATCH($B229,Shelter_Design!$A$2:$A$41,0)) -> 0.5 | AE229: SYNTHETIC - scenario built by pairing a prototype shelter design with representative monthly climatology; not a record of a real, physically deployed shelter.

Sheet Output_Benefits
A1: Scenario_ID | B1: Estimated_ACH | C1: Ventilation_Loss_Coefficient_WK | D1: Conductive_Loss_Coefficient_WK | E1: Total_Loss_Coefficient_WK | F1: Effective_Solar_Aperture_m2 | G1: Estimated_Heat_Gain_W | H1: Estimated_Indoor_Temperature_C | I1: Indoor_Outdoor_Temp_Difference_C | J1: Estimated_Heat_Loss_W | K1: Adaptive_Comfort_Neutral_Temp_C | L1: Adaptive_Comfort_Deviation_C | M1: Comfort_Band_Status | N1: Comfort_Score_0to100 | O1: PMV_Approximate_LowConfidence | P1: PPD_Approximate_pct_LowConfidence | Q1: Estimated_Heating_Requirement_W | R1: Estimated_Cooling_Requirement_W | S1: Energy_Requirement_W | T1: Thermal_Performance_Score_0to100 | U1: Overall_Shelter_Suitability_Score_0to100 | V1: Recommended_Status | W1: Primary_Recommendation_Reason | X1: Data_Source_Label
A2: =Combined_Scenarios!A2 -> S001 | B2: =0.5+Combined_Scenarios!AA2*10 -> 0.91666667 | C2: =0.33*B2*Combined_Scenarios!Z2 -> 6.534 | D2: =Combined_Scenarios!W2*Combined_Scenarios!X2 -> 5.26574 | E2: =C2+D2 -> 11.79974 | F2: =0.5*Combined_Scenarios!Y2 -> 0.6 | G2: =Combined_Scenarios!K2*F2 -> 100 | H2: =Combined_Scenarios!H2+IF(E2=0,0,G2/E2) -> 0.47476301 | I2: =H2-Combined_Scenarios!H2 -> 8.474763 | J2: =E2*I2 -> 100 | K2: =0.31*Combined_Scenarios!H2+17.8 -> 15.32 | L2: =H2-K2 -> -14.845237 | M2: =IF(AND(H2>=12,H2<=35),"Within safe range","Outside safe range") -> Outside safe range | N2: =MAX(0,100-ABS(L2)*8) -> 0 | O2: =MAX(-3,MIN(3,L2/3)) -> -3 | P2: =100-95*EXP(-(0.03353*O2^4+0.2179*O2^2)) -> 99.115872 | Q2: =IF(H2<18,E2*(18-H2),0) -> 206.79324 | R2: =IF(H2>26,E2*(H2-26),0) -> 0 | S2: =Q2+R2 -> 206.79324 | T2: =MAX(0,100-S2/5) -> 58.641352 | U2: =(N2+T2)/2 -> 29.320676 | V2: =IF(U2>=60,"Recommended","Not Recommended") -> Not Recommended | W2: =IF(Q2>0,"Increase insulation thickness or reduce opening area to cut heat loss",IF(R2>0,"Increase shading/ventilation or reduce solar-facing openings to cut heat gain","Design meets estimated comfort band without major changes")) -> Increase insulation thickness or reduce opening area to cut heat loss | X2: SYNTHETIC/ESTIMATED - computed via a simplified steady-state heat-balance approximation (single-node lumped model) for prototype purposes. This is NOT an ANSYS/CFD simulation result. Must be replaced or validated with proper thermal simulation, ANSYS modelling, or physical testing before final submission.
A3: =Combined_Scenarios!A3 -> S002 | B3: =0.5+Combined_Scenarios!AA3*10 -> 0.91666667 | C3: =0.33*B3*Combined_Scenarios!Z3 -> 6.534 | D3: =Combined_Scenarios!W3*Combined_Scenarios!X3 -> 5.26574 | E3: =C3+D3 -> 11.79974 | F3: =0.5*Combined_Scenarios!Y3 -> 0.6 | G3: =Combined_Scenarios!K3*F3 -> 162.5 | H3: =Combined_Scenarios!H3+IF(E3=0,0,G3/E3) -> 20.77149 | I3: =H3-Combined_Scenarios!H3 -> 13.77149 | J3: =E3*I3 -> 162.5 | K3: =0.31*Combined_Scenarios!H3+17.8 -> 19.97 | L3: =H3-K3 -> 0.8014899 | M3: =IF(AND(H3>=12,H3<=35),"Within safe range","Outside safe range") -> Within safe range | N3: =MAX(0,100-ABS(L3)*8) -> 93.588081 | O3: =MAX(-3,MIN(3,L3/3)) -> 0.2671633 | P3: =100-95*EXP(-(0.03353*O3^4+0.2179*O3^2)) -> 6.4820693 | Q3: =IF(H3<18,E3*(18-H3),0) -> 0 | R3: =IF(H3>26,E3*(H3-26),0) -> 0 | S3: =Q3+R3 -> 0 | T3: =MAX(0,100-S3/5) -> 100 | U3: =(N3+T3)/2 -> 96.79404 | V3: =IF(U3>=60,"Recommended","Not Recommended") -> Recommended | W3: =IF(Q3>0,"Increase insulation thickness or reduce opening area to cut heat loss",IF(R3>0,"Increase shading/ventilation or reduce solar-facing openings to cut heat gain","Design meets estimated comfort band without major changes")) -> Design meets estimated comfort band without major changes | X3: SYNTHETIC/ESTIMATED - computed via a simplified steady-state heat-balance approximation (single-node lumped model) for prototype purposes. This is NOT an ANSYS/CFD simulation result. Must be replaced or validated with proper thermal simulation, ANSYS modelling, or physical testing before final submission.
A4: =Combined_Scenarios!A4 -> S003 | B4: =0.5+Combined_Scenarios!AA4*10 -> 0.91666667 | C4: =0.33*B4*Combined_Scenarios!Z4 -> 6.534 | D4: =Combined_Scenarios!W4*Combined_Scenarios!X4 -> 5.26574 | E4: =C4+D4 -> 11.79974 | F4: =0.5*Combined_Scenarios!Y4 -> 0.6 | G4: =Combined_Scenarios!K4*F4 -> 170 | H4: =Combined_Scenarios!H4+IF(E4=0,0,G4/E4) -> 33.407097 | I4: =H4-Combined_Scenarios!H4 -> 14.407097 | J4: =E4*I4 -> 170 | K4: =0.31*Combined_Scenarios!H4+17.8 -> 23.69 | L4: =H4-K4 -> 9.7170971 | M4: =IF(AND(H4>=12,H4<=35),"Within safe range","Outside safe range") -> Within safe range | N4: =MAX(0,100-ABS(L4)*8) -> 22.263223 | O4: =MAX(-3,MIN(3,L4/3)) -> 3 | P4: =100-95*EXP(-(0.03353*O4^4+0.2179*O4^2)) -> 99.115872 | Q4: =IF(H4<18,E4*(18-H4),0) -> 0 | R4: =IF(H4>26,E4*(H4-26),0) -> 87.40182 | S4: =Q4+R4 -> 87.40182 | T4: =MAX(0,100-S4/5) -> 82.519636 | U4: =(N4+T4)/2 -> 52.391429 | V4: =IF(U4>=60,"Recommended","Not Recommended") -> Not Recommended | W4: =IF(Q4>0,"Increase insulation thickness or reduce opening area to cut heat loss",IF(R4>0,"Increase shading/ventilation or reduce solar-facing openings to cut heat gain","Design meets estimated comfort band without major changes")) -> Increase shading/ventilation or reduce solar-facing openings to cut heat gain | X4: SYNTHETIC/ESTIMATED - computed via a simplified steady-state heat-balance approximation (single-node lumped model) for prototype purposes. This is NOT an ANSYS/CFD simulation result. Must be replaced or validated with proper thermal simulation, ANSYS modelling, or physical testing before final submission.
